<?xml version="1.0" ?>
<!-- =================================================================================== -->
<!-- |    This document was autogenerated by xacro from TB.xacro                       | -->
<!-- |    EDITING THIS FILE BY HAND IS NOT RECOMMENDED                                 | -->
<!-- =================================================================================== -->
<robot name="kbot">
  <!--Color Properties-->
  <material name="blue">
    <color rgba="0 0 0.8 1"/>
  </material>
  <material name="black">
    <color rgba="0 0 0 1"/>
  </material>
  <material name="white">
    <color rgba="1 1 1 1"/>
  </material>
  <material name="red">
    <color rgba="0.8 0.0 0.0 1.0"/>
  </material>
  <!--Base Footprint-->
  <link name="base_footprint">
    <inertial>
      <mass value="10"/>
      <inertia ixx="1.6666666666666667e-06" ixy="0.0" ixz="0.0" iyy="1.6666666666666667e-06" iyz="0.0" izz="1.6666666666666667e-06"/>
    </inertial>
    <visual>
      <origin rpy="0 0 0" xyz="0 0 0"/>
      <geometry>
        <box size="0.001 0.001 0.001"/>
      </geometry>
    </visual>
  </link>
  <!--Base link-->
  <link name="base_link">
    <inertial>
      <mass value="1"/>
      <inertia ixx="0.0021416666666666667" ixy="0.0" ixz="0.0" iyy="0.004266666666666667" iyz="0.0" izz="0.0021416666666666667"/>
    </inertial>
    <visual>
      <geometry>
        <box size="0.16 0.16 0.01"/>
      </geometry>
      <material name="black"/>
    </visual>
    <collision>
      <geometry>
        <box size="0.16 0.16 0.01"/>
      </geometry>
    </collision>
  </link>
  <!--base_link to base_footprint Joint-->
  <joint name="base_link_joint" type="fixed">
    <origin rpy="0 0 0" xyz="0 0 0.04"/>
    <parent link="base_footprint"/>
    <child link="base_link"/>
  </joint>
  <link name="left_wheel">
    <visual>
      <origin rpy="1.5707963267948966 0 0" xyz="0 0 0"/>
      <geometry>
        <cylinder length="0.005" radius="0.035"/>
      </geometry>
      <material name="red"/>
    </visual>
    <collision>
      <origin rpy="1.5707963267948966 0 0" xyz="0 0 0"/>
      <geometry>
        <cylinder length="0.005" radius="0.035"/>
      </geometry>
    </collision>
    <inertial>
      <mass value="1"/>
      <inertia ixx="0.00030833333333333337" ixy="0" ixz="0" iyy="0.00030833333333333337" iyz="0" izz="0.0006125000000000001"/>
    </inertial>
  </link>
  <joint name="left_wheel_joint" type="continuous">
    <axis rpy="0 0 0" xyz="0 1 0"/>
    <parent link="base_link"/>
    <child link="left_wheel"/>
    <origin rpy="0 0 0" xyz="0.02 0.08700000000000001 -0.005"/>
  </joint>
  <link name="right_wheel">
    <visual>
      <origin rpy="1.5707963267948966 0 0" xyz="0 0 0"/>
      <geometry>
        <cylinder length="0.005" radius="0.035"/>
      </geometry>
      <material name="red"/>
    </visual>
    <collision>
      <origin rpy="1.5707963267948966 0 0" xyz="0 0 0"/>
      <geometry>
        <cylinder length="0.005" radius="0.035"/>
      </geometry>
    </collision>
    <inertial>
      <mass value="1"/>
      <inertia ixx="0.00030833333333333337" ixy="0" ixz="0" iyy="0.00030833333333333337" iyz="0" izz="0.0006125000000000001"/>
    </inertial>
  </link>
  <joint name="right_wheel_joint" type="continuous">
    <axis rpy="0 0 0" xyz="0 1 0"/>
    <parent link="base_link"/>
    <child link="right_wheel"/>
    <origin rpy="0 0 0" xyz="0.02 -0.08700000000000001 -0.005"/>
  </joint>
  <!--Caster Wheel Link-->
  <link name="caster_wheel">
    <visual>
      <origin rpy="0 0 0" xyz="0 0 0"/>
      <geometry>
        <sphere radius="0.0175"/>
      </geometry>
      <material name="blue"/>
    </visual>
    <collision>
      <origin rpy="0 0 0" xyz="0 0 0"/>
      <geometry>
        <sphere radius="0.0175"/>
      </geometry>
    </collision>
    <inertial>
      <mass value="1"/>
      <inertia ixx="0.00012250000000000002" ixy="0.0" ixz="0.0" iyy="0.00012250000000000002" iyz="0.0" izz="0.00012250000000000002"/>
    </inertial>
  </link>
  <!--Caster Wheel Joint-->
  <joint name="caster_wheel_joint" type="continuous">
    <axis rpy="0 0 0" xyz="0 1 0"/>
    <parent link="base_link"/>
    <child link="caster_wheel"/>
    <origin rpy="0 0 0" xyz="-0.052 0 -0.022500000000000003"/>
  </joint>
</robot>
